Error in print(x, ...) : object 'Table_2' not found 
Traceback: 
[1] "2: print(x, ...)"      "1: log_print(Table_2)"

